<?xml version="1.0" ?>
<!-- =================================================================================== -->
<!-- |    This document was autogenerated by xacro from /home/dave/ros/ws_gazebo/src/gazebo_ros_demos/rrbot_description/urdf/rrbot.xacro | -->
<!-- |    EDITING THIS FILE BY HAND IS NOT RECOMMENDED                                 | -->
<!-- =================================================================================== -->
<!-- Revolute-Revolute Manipulator -->
<robot name="invpend" xmlns:xacro="http://www.ros.org/wiki/xacro">
  <!-- Constants for robot dimensions -->
  <xacro:property name="PI" value="3.1415926535897931"/>
  <xacro:property name="mass_slider" value="100" /> <!-- arbitrary value for mass -->
  <xacro:property name="mass_cart" value="1.0" /> <!-- arbitrary value for mass -->
  <xacro:property name="mass_pole" value="0.1" /> <!-- arbitrary value for mass -->
  <xacro:property name="width" value="0.25" /> <!-- cart width -->
  <xacro:property name="height" value="0.125" /> <!-- cart height -->
  <xacro:property name="depth" value="0.25" /> <!-- cart depth -->
  <xacro:property name="length_slider" value="5" /> <!-- pole length -->
  <xacro:property name="length_pole" value="0.5" /> <!-- pole length -->
  <xacro:property name="radius" value="0.01" /> <!-- slender bar radius -->
  <xacro:property name="radius_pole" value="0.025" /> <!-- pole radius -->
  
  <!-- Import all Gazebo-customization elements, including Gazebo colors -->
  <gazebo>
    <plugin filename="libgazebo_ros_control.so" name="ros_control">
      <robotNamespace>/invpend</robotNamespace>
    </plugin>
  </gazebo>
  <gazebo reference="slidebar">
    <material>Gazebo/Black</material>
  </gazebo>
  <gazebo reference="cart">
    <!--mu1>0.2</mu1>
    <mu2>0.2</mu2-->
    <material>Gazebo/Blue</material>
  </gazebo>
  <gazebo reference="pole">
    <!--mu1>0.2</mu1>
    <mu2>0.2</mu2-->
    <material>Gazebo/Orange</material>
  </gazebo>
  <!-- Import Rviz colors -->
  <material name="black">
    <color rgba="0.0 0.0 0.0 1.0"/>
  </material>
  <material name="blue">
    <color rgba="0.0 0.0 0.8 1.0"/>
  </material>
  <material name="green">
    <color rgba="0.0 0.8 0.0 1.0"/>
  </material>
  <material name="grey">
    <color rgba="0.2 0.2 0.2 1.0"/>
  </material>
  <material name="orange">
    <color rgba="1.0 0.423529411765 0.0392156862745 1.0"/>
  </material>
  <material name="brown">
    <color rgba="0.870588235294 0.811764705882 0.764705882353 1.0"/>
  </material>
  <material name="red">
    <color rgba="0.8 0.0 0.0 1.0"/>
  </material>
  <material name="white">
    <color rgba="1.0 1.0 1.0 1.0"/>
  </material>
  <!-- Used for fixing robot to Gazebo 'base_link' -->
  <link name="world"/>

  <joint name="fixed" type="fixed">
    <parent link="world"/>
    <child link="slidebar"/>
    <origin xyz="0 0 2"/>
  </joint>

  <!-- Slider Link -->
  <link name="slidebar">
    <visual>
      <origin xyz="0 0 0" rpy="0 0 0"/>
      <geometry>
	<box size="${length_slider} ${radius} ${radius}"/>
      </geometry>
      <material name="black"/>
    </visual>

    <inertial>
      <origin xyz="0 0 0" rpy="0 0 0"/>
      <mass value="${mass_slider}"/>
      <inertia
	  ixx="${mass_slider*length_slider*length_slider/12}" ixy="0.0" ixz="0.0"
	  iyy="0.0" iyz="0.0"
	  izz="${mass_slider*length_slider*length_slider/12}"/>
    </inertial>
  </link>

  <joint name="slider_to_cart" type="prismatic">
    <parent link="slidebar"/>
    <child link="cart"/>
    <origin xyz="0 0 0" rpy="0 0 0"/>
    <axis xyz="1 0 0"/>
    <limit effort="100.0" lower="-2.5" upper="2.5" velocity="1000"/>
    <!--dynamics damping="0.0001"/-->
  </joint>

  <!-- Cart Link -->
  <link name="cart">
    <collision>
      <origin xyz="0 0 0" rpy="0 0 0"/>
      <geometry>
	<box size="${width} ${depth} ${height}"/>
      </geometry>
    </collision>

    <visual>
      <origin xyz="0 0 0" rpy="0 0 0"/>
      <geometry>
	<box size="${width} ${depth} ${height}"/>	
      </geometry>
      <material name="blue"/>
    </visual>

    <inertial>
      <origin xyz="0 0 0" rpy="0 0 0"/>
      <mass value="${mass_cart}"/>
      <inertia
	  ixx="${mass_cart*(depth*depth+height*height)/12}" ixy="0.0" ixz="0.0"
	  iyy="${mass_cart*(depth*depth+width*width)/12}" iyz="0.0"
	  izz="${mass_cart*(width*width+height*height)/12}"/>
    </inertial>
  </link>

  <joint name="cart_to_pole" type="revolute">
    <parent link="cart"/>
    <child link="pole"/>
    <origin xyz="0 -0.15 0" rpy="0 0 0"/>
    <axis xyz="0 1 0"/>
    <limit effort="1000.0" lower="${-PI}" upper = "${PI}" velocity="1000.0"/>
  </joint>

  <!-- Pole Link -->
  <link name="pole">
    <collision>
      <origin xyz="0 0 0.25" rpy="0 0 0"/>
      <geometry>
	<box size="${radius} ${radius} ${length_pole}"/>
      </geometry>
    </collision>

    <visual>
      <origin xyz="0 0 0.25" rpy="0 0 0"/>
      <geometry>
	<box size="${radius} ${radius} ${length_pole}"/>
      </geometry>
      <material name="orange"/>
    </visual>

    <inertial>
      <origin xyz="0 0 0.25" rpy="0 0 0"/>
      <mass value="${mass_pole}"/>
      <inertia
	  ixx="${mass_pole*length_pole*length_pole/3}" ixy="0.0" ixz="0.0"
	  iyy="0.0" iyz="0.0"
	  izz="${mass_pole*length_pole*length_pole/3}"/>
    </inertial>
  </link>
  <transmission name="tran1">
    <type>transmission_interface/SimpleTransmission</type>
    <joint name="slider_to_cart"/>
    <actuator name="motor_pris">
      <hardwareInterface>EffortJointInterface</hardwareInterface>
      <mechanicalReduction>1</mechanicalReduction>
    </actuator>
  </transmission>
  <transmission name="tran2">
    <type>transmission_interface/SimpleTransmission</type>
    <joint name="cart_to_pole"/>
    <actuator name="motor_revo">
      <hardwareInterface>EffortJointInterface</hardwareInterface>
      <mechanicalReduction>1</mechanicalReduction>
    </actuator>
  </transmission>
</robot>
<?xml version="1.0" ?>
<!-- =================================================================================== -->
<!-- |    This document was autogenerated by xacro from /home/linzhank/ros_ws/src/invpend_experiment/invpend_description/urdf/invpend.xacro | -->
<!-- |    EDITING THIS FILE BY HAND IS NOT RECOMMENDED                                 | -->
<!-- =================================================================================== -->
<!-- Revolute-Revolute Manipulator -->
<robot name="invpend" xmlns:xacro="http://www.ros.org/wiki/xacro">
  <!-- Space btw top of beam and the each joint -->
  <!-- ros_control plugin -->
  <gazebo>
    <plugin filename="libgazebo_ros_control.so" name="gazebo_ros_control">
      <robotNamespace>/invpend</robotNamespace>
      <robotSimType>gazebo_ros_control/DefaultRobotHWSim</robotSimType>
    </plugin>
  </gazebo>
  <!-- Slider Link -->
  <gazebo reference="slidebar">
    <material>Gazebo/Black</material>
  </gazebo>
  <!-- Cart Link -->
  <gazebo reference="cart">
    <mu1>0.2</mu1>
    <mu2>0.2</mu2>
    <material>Gazebo/Blue</material>
  </gazebo>
  <!-- Pole Link -->
  <gazebo reference="pole">
    <mu1>0.2</mu1>
    <mu2>0.2</mu2>
    <material>Gazebo/Orange</material>
  </gazebo>
  <material name="black">
    <color rgba="0.0 0.0 0.0 1.0"/>
  </material>
  <material name="blue">
    <color rgba="0.0 0.0 0.8 1.0"/>
  </material>
  <material name="green">
    <color rgba="0.0 0.8 0.0 1.0"/>
  </material>
  <material name="grey">
    <color rgba="0.2 0.2 0.2 1.0"/>
  </material>
  <material name="orange">
    <color rgba="1.0 0.423529411765 0.0392156862745 1.0"/>
  </material>
  <material name="brown">
    <color rgba="0.870588235294 0.811764705882 0.764705882353 1.0"/>
  </material>
  <material name="red">
    <color rgba="0.8 0.0 0.0 1.0"/>
  </material>
  <material name="white">
    <color rgba="1.0 1.0 1.0 1.0"/>
  </material>
  <!-- Used for fixing robot to Gazebo 'base_link' -->
  <link name="world"/>
  <joint name="fixed" type="fixed">
    <parent link="world"/>
    <child link="slidebar"/>
  </joint>
  <!-- Slider Link -->
  <link name="slidebar">
    <visual>
      <origin rpy="0 0 0" xyz="0 0 2"/>
      <geometry>
        <box size="10 0.05 0.05"/>
      </geometry>
      <material name="black"/>
    </visual>
    <inertial>
      <origin rpy="0 0 0" xyz="0 0 2"/>
      <mass value="1000"/>
      <inertia ixx="1.0" ixy="0.0" ixz="0.0" iyy="1.0" iyz="0.0" izz="1.0"/>
    </inertial>
  </link>
  <joint name="slider_to_cart" type="prismatic">
    <parent link="slidebar"/>
    <child link="cart"/>
    <origin rpy="0 0 0" xyz="0 0 2"/>
    <axis xyz="1 0 0"/>
    <limit effort="1000.0" lower="-5" upper="5" velocity="100"/>
    <dynamics damping="0.01"/>
  </joint>
  <!-- Cart Link -->
  <link name="cart">
    <collision>
      <origin rpy="0 0 0" xyz="0 0 0"/>
      <geometry>
        <box size="0.5 0.5 0.2"/>
      </geometry>
    </collision>
    <visual>
      <origin rpy="0 0 0" xyz="0 0 0"/>
      <geometry>
        <box size="0.5 0.5 0.2"/>
      </geometry>
      <material name="blue"/>
    </visual>
    <inertial>
      <origin rpy="0 0 0" xyz="0 0 0"/>
      <mass value="1"/>
      <inertia ixx="1.0" ixy="0.0" ixz="0.0" iyy="1.0" iyz="0.0" izz="1.0"/>
    </inertial>
  </link>
  <joint name="cart_to_pole" type="continuous">
    <parent link="cart"/>
    <child link="pole"/>
    <origin rpy="0 0 0" xyz="0 -0.25 0"/>
    <axis xyz="0 1 0"/>
    <dynamics damping="0.001"/>
  </joint>
  <!-- Pole Link -->
  <link name="pole">
    <collision>
      <origin rpy="0 0 0" xyz="0 0 0.5"/>
      <geometry>
        <box size="0.05 0.05 1"/>
      </geometry>
    </collision>
    <visual>
      <origin rpy="0 0 0" xyz="0 0 0.5"/>
      <geometry>
        <box size="0.05 0.05 1"/>
      </geometry>
      <material name="orange"/>
    </visual>
    <inertial>
      <origin rpy="0 0 0" xyz="0 0 0.5"/>
      <mass value="3"/>
      <inertia ixx="1.0" ixy="0.0" ixz="0.0" iyy="1.0" iyz="0.0" izz="1.0"/>
    </inertial>
  </link>
  <transmission name="tran1">
    <type>transmission_interface/SimpleTransmission</type>
    <joint name="slider_to_cart">
      <hardwareInterface>hardware_interface/EffortJointInterface</hardwareInterface>
    </joint>
    <actuator name="motor_pris">
      <hardwareInterface>hardware_interface/EffortJointInterface</hardwareInterface>
      <mechanicalReduction>1</mechanicalReduction>
    </actuator>
  </transmission>
  <transmission name="tran2">
    <type>transmission_interface/SimpleTransmission</type>
    <joint name="cart_to_pole">
      <hardwareInterface>hardware_interface/EffortJointInterface</hardwareInterface>
    </joint>
    <actuator name="motor_revo">
      <hardwareInterface>hardware_interface/EffortJointInterface</hardwareInterface>
      <mechanicalReduction>1</mechanicalReduction>
    </actuator>
  </transmission>
</robot>

